Workbook
Name NativeTimeline_Date: #N/A
Name Slicer_Direction: #N/A
Name Slicer_Sales_Person_Name: #N/A

Sheet Pivot_Tables
A3: Row Labels | B3: Sum of Total calls | C3: Sum of Incoming Flag | D3: Sum of Completed calls | E3: Sum of Completed Incoming | F3: Sum of CONVERSION Rate | G3: Sum of Price for a call | J3: Sum of Total calls2
A4: Aarav Sharma | B4: 8 | C4: 3 | D4: 3 | E4: 1 | F4: 3 | G4: 3.9 | J4: 368
A5: Abdul Usman Ali | B5: 1 | C5: 1 | D5: 0 | E5: 0 | F5: 0
A6: Abhishek Jain | B6: 7 | C6: 2 | D6: 3 | E6: 2 | F6: 3 | G6: 7.95
A7: Aditi Shah | B7: 7 | C7: 3 | D7: 5 | E7: 2 | F7: 5 | G7: 4.65
A8: Aditya Rao | B8: 8 | C8: 3 | D8: 5 | E8: 3 | F8: 5 | G8: 17.5
A9: Akash Singh | B9: 8 | C9: 5 | D9: 4 | E9: 3 | F9: 4 | G9: 12.75
A10: Amit Kulkarni | B10: 8 | C10: 4 | D10: 5 | E10: 4 | F10: 5 | G10: 4.3
A11: Ananya Sharma | B11: 7 | C11: 5 | D11: 4 | E11: 2 | F11: 4 | G11: 3.55
A12: Anjali Menon | B12: 7 | C12: 4 | D12: 5 | E12: 4 | F12: 5 | G12: 17.15
A13: Anto Abhishek | B13: 1 | C13: 0 | D13: 1 | E13: 0 | F13: 1 | G13: 3.85
A14: Arjun Nair | B14: 7 | C14: 3 | D14: 3 | E14: 1 | F14: 3 | G14: 6.25
A15: Deepak Yadav | B15: 7 | C15: 1 | D15: 3 | E15: 1 | F15: 3 | G15: 5.55 | J15: Row Labels | K15: Sum of Total calls
A16: Divya Rao | B16: 7 | C16: 4 | D16: 4 | E16: 2 | F16: 4 | G16: 29.05 | J16: busy | K16: 1
A17: Gaurav Mishra | B17: 7 | C17: 4 | D17: 3 | E17: 2 | F17: 3 | G17: 12.2 | J17: call-attempt | K17: 64
A18: Harsh Patel | B18: 7 | C18: 5 | D18: 5 | E18: 3 | F18: 5 | G18: 12.35 | J18: completed | K18: 175
A19: Hyderali Meer | B19: 8 | C19: 0 | D19: 4 | E19: 0 | F19: 4 | G19: 6.2 | J19: failed | K19: 51
A20: Ishita Kapoor | B20: 8 | C20: 4 | D20: 4 | E20: 2 | F20: 4 | G20: 9.5 | J20: missed-call | K20: 35
A21: Karan Malhotra | B21: 7 | C21: 2 | D21: 4 | E21: 1 | F21: 4 | G21: 11.25 | J21: no-answer | K21: 42
A22: Kavya Menon | B22: 7 | C22: 2 | D22: 3 | E22: 1 | F22: 3 | G22: 13.6 | J22: Grand Total | K22: 368
A23: Kriti Singh | B23: 8 | C23: 4 | D23: 4 | E23: 2 | F23: 4 | G23: 10.35
A24: Manish Kumar | B24: 7 | C24: 6 | D24: 5 | E24: 5 | F24: 5 | G24: 10
A25: Martin Nerella | B25: 1 | C25: 1 | D25: 0 | E25: 0 | F25: 0
A26: Meera Joshi | B26: 8 | C26: 4 | D26: 3 | E26: 3 | F26: 3 | G26: 3.2
A27: N/A | B27: 47 | C27: 47 | D27: 17 | E27: 17 | F27: 17 | G27: 46
A28: Nandini Das | B28: 8 | C28: 4 | D28: 4 | E28: 3 | F28: 4 | G28: 14
A29: Neha Gupta | B29: 7 | C29: 5 | D29: 2 | E29: 2 | F29: 2 | G29: 2
A30: Nikhil Kapoor | B30: 8 | C30: 2 | D30: 6 | E30: 2 | F30: 6 | G30: 12.25 | J30: Row Labels | K30: Sum of Total calls
A31: Nirag K A | B31: 2 | C31: 0 | D31: 0 | E31: 0 | F31: 0 | G31: 0.8 | J31: Aug | K31: 368
A32: Nisha Verma | B32: 8 | C32: 4 | D32: 5 | E32: 1 | F32: 5 | G32: 5.4 | J32: Grand Total | K32: 368
A33: Nishanth D Shekar | B33: 1 | C33: 1 | D33: 1 | E33: 1 | F33: 1 | G33: 0.4
A34: Pallavi Rao | B34: 8 | C34: 3 | D34: 4 | E34: 0 | F34: 4 | G34: 6.2
A35: Pooja Shah | B35: 8 | C35: 4 | D35: 3 | E35: 1 | F35: 3 | G35: 6.35
A36: Priya Nair | B36: 7 | C36: 2 | D36: 3 | E36: 1 | F36: 3 | G36: 3.6
A37: Rahul Kumar | B37: 1 | C37: 0 | D37: 1 | E37: 0 | F37: 1 | G37: 0.8
A38: Rahul Verma | B38: 8 | C38: 5 | D38: 3 | E38: 2 | F38: 3 | G38: 8
A39: Riya Mehta | B39: 8 | C39: 6 | D39: 2 | E39: 2 | F39: 2 | G39: 5.2
A40: Rohan Mehta | B40: 8 | C40: 3 | D40: 4 | E40: 2 | F40: 4 | G40: 6.4 | J40: Row Labels | K40: Average of CONVERSION Rate
A41: Rohit Das | B41: 8 | C41: 3 | D41: 3 | E41: 2 | F41: 3 | G41: 8.75 | J41: Aarav Sharma | K41: 0.375
A42: Sakshi Joshi | B42: 7 | C42: 3 | D42: 4 | E42: 2 | F42: 4 | G42: 6 | J42: Abdul Usman Ali | K42: 0
...

Sheet Raw_Data
A1: Call ID | B1: Direction | C1: CallKaro Number | D1: Sales Person Number | E1: Sales Person Name | F1: Cust Name | G1: Cust Number | H1: Status of Call | I1: Completed calls | J1: Total calls | K1: CONVERSION Rate | L1: Incoming Flag | M1: Outgoing Flag | N1: Completed Incoming | O1: Date | P1: StartTime | Q1: EndTime | R1: Duration of call (in Sec) | S1: MISSED-Failed-no answer | T1: Price for a call | U1: Sales Person Location | V1: Customer Location | W1: Column1
A2: C105 | B2: Incoming | C2: 8099389567 | D2: 224885655 | E2: Sanjay Nair | F2: Pooja Shah | G2: 1000000014 | H2: call-attempt | I2: =IF(SalesData[[#This Row],[Status of Call]]="completed",1,0) -> 0 | J2: =1 -> 1 | K2: =SalesData[[#This Row],[Completed calls]]/SalesData[[#This Row],[Total calls]] -> 0 | L2: =IF(B2="incoming",1,0) -> 1 | M2: =IF(B2="Outgoing",1,0) -> 0 | N2: =IF(AND(B2="Incoming",H2="Completed"),1,0) -> 0 | O2: 46237 | P2: 46237.517 | Q2: 46237.517 | R2: 8 | S2: =IF(OR(H2="failed",H2="no-answer",H2="missed-call"),1,0) -> 0 | U2: GJ | V2: KA
A3: C111 | B3: Incoming | C3: 8099389567 | D3: 900417386 | E3: Pooja Shah | F3: Aditya Rao | G3: 1000000009 | H3: call-attempt | I3: =IF(SalesData[[#This Row],[Status of Call]]="completed",1,0) -> 0 | J3: =1 -> 1 | K3: =SalesData[[#This Row],[Completed calls]]/SalesData[[#This Row],[Total calls]] -> 0 | L3: =IF(B3="incoming",1,0) -> 1 | M3: =IF(B3="Outgoing",1,0) -> 0 | N3: =IF(AND(B3="Incoming",H3="Completed"),1,0) -> 0 | O3: 46237 | P3: 46237.52 | Q3: 46237.52 | R3: 21 | S3: =IF(OR(H3="failed",H3="no-answer",H3="missed-call"),1,0) -> 0 | U3: KA | V3: KA
A4: C112 | B4: Incoming | C4: 8099389567 | D4: 577506333 | E4: Akash Singh | F4: Ishita Gupta | G4: 1000000016 | H4: completed | I4: =IF(SalesData[[#This Row],[Status of Call]]="completed",1,0) -> 1 | J4: =1 -> 1 | K4: =SalesData[[#This Row],[Completed calls]]/SalesData[[#This Row],[Total calls]] -> 1 | L4: =IF(B4="incoming",1,0) -> 1 | M4: =IF(B4="Outgoing",1,0) -> 0 | N4: =IF(AND(B4="Incoming",H4="Completed"),1,0) -> 1 | O4: 46237 | P4: 46237.52 | Q4: 46237.525 | R4: 426 | S4: =IF(OR(H4="failed",H4="no-answer",H4="missed-call"),1,0) -> 0 | T4: 2.8 | U4: KA | V4: KA
A5: C115 | B5: Incoming | C5: 8099389567 | D5: 432798330 | E5: Priya Nair | F5: Rohan Das | G5: 1000000017 | H5: completed | I5: =IF(SalesData[[#This Row],[Status of Call]]="completed",1,0) -> 1 | J5: =1 -> 1 | K5: =SalesData[[#This Row],[Completed calls]]/SalesData[[#This Row],[Total calls]] -> 1 | L5: =IF(B5="incoming",1,0) -> 1 | M5: =IF(B5="Outgoing",1,0) -> 0 | N5: =IF(AND(B5="Incoming",H5="Completed"),1,0) -> 1 | O5: 46237 | P5: 46237.522 | Q5: 46237.523 | R5: 97 | S5: =IF(OR(H5="failed",H5="no-answer",H5="missed-call"),1,0) -> 0 | T5: 0.4 | U5: KA | V5: KA
A6: C117 | B6: Incoming | C6: 8099389567 | D6: 925746665 | E6: Anjali Menon | F6: Simran Kaur | G6: 1000000028 | H6: completed | I6: =IF(SalesData[[#This Row],[Status of Call]]="completed",1,0) -> 1 | J6: =1 -> 1 | K6: =SalesData[[#This Row],[Completed calls]]/SalesData[[#This Row],[Total calls]] -> 1 | L6: =IF(B6="incoming",1,0) -> 1 | M6: =IF(B6="Outgoing",1,0) -> 0 | N6: =IF(AND(B6="Incoming",H6="Completed"),1,0) -> 1 | O6: 46237 | P6: 46237.538 | Q6: 46237.547 | R6: 768 | S6: =IF(OR(H6="failed",H6="no-answer",H6="missed-call"),1,0) -> 0 | T6: 5.2 | U6: KA | V6: KA
A7: C125 | B7: Incoming | C7: 8099389567 | D7: 18831166 | E7: Shreya Iyer | F7: Priya Iyer | G7: 1000000006 | H7: call-attempt | I7: =IF(SalesData[[#This Row],[Status of Call]]="completed",1,0) -> 0 | J7: =1 -> 1 | K7: =SalesData[[#This Row],[Completed calls]]/SalesData[[#This Row],[Total calls]] -> 0 | L7: =IF(B7="incoming",1,0) -> 1 | M7: =IF(B7="Outgoing",1,0) -> 0 | N7: =IF(AND(B7="Incoming",H7="Completed"),1,0) -> 0 | O7: 46237 | P7: 46237.557 | Q7: 46237.557 | R7: 7 | S7: =IF(OR(H7="failed",H7="no-answer",H7="missed-call"),1,0) -> 0 | U7: RJ | V7: KA
A8: C126 | B8: Incoming | C8: 8099389567 | D8: 858283693 | E8: Meera Joshi | F8: Ananya Nair | G8: 1000000004 | H8: completed | I8: =IF(SalesData[[#This Row],[Status of Call]]="completed",1,0) -> 1 | J8: =1 -> 1 | K8: =SalesData[[#This Row],[Completed calls]]/SalesData[[#This Row],[Total calls]] -> 1 | L8: =IF(B8="incoming",1,0) -> 1 | M8: =IF(B8="Outgoing",1,0) -> 0 | N8: =IF(AND(B8="Incoming",H8="Completed"),1,0) -> 1 | O8: 46237 | P8: 46237.571 | Q8: 46237.572 | R8: 34 | S8: =IF(OR(H8="failed",H8="no-answer",H8="missed-call"),1,0) -> 0 | T8: 0.4 | U8: KA | V8: KA
A9: C127 | B9: Incoming | C9: 8099389567 | D9: 913511869 | E9: Karan Malhotra | F9: Sneha Reddy | G9: 1000000008 | H9: missed-call | I9: =IF(SalesData[[#This Row],[Status of Call]]="completed",1,0) -> 0 | J9: =1 -> 1 | K9: =SalesData[[#This Row],[Completed calls]]/SalesData[[#This Row],[Total calls]] -> 0 | L9: =IF(B9="incoming",1,0) -> 1 | M9: =IF(B9="Outgoing",1,0) -> 0 | N9: =IF(AND(B9="Incoming",H9="Completed"),1,0) -> 0 | O9: 46237 | P9: 46237.573 | Q9: 46237.574 | R9: 46 | S9: =IF(OR(H9="failed",H9="no-answer",H9="missed-call"),1,0) -> 1 | U9: KA | V9: KA
A10: C128 | B10: Incoming | C10: 8099389567 | D10: 832577930 | E10: Rohan Mehta | F10: Meera Joshi | G10: 1000000010 | H10: completed | I10: =IF(SalesData[[#This Row],[Status of Call]]="completed",1,0) -> 1 | J10: =1 -> 1 | K10: =SalesData[[#This Row],[Completed calls]]/SalesData[[#This Row],[Total calls]] -> 1 | L10: =IF(B10="incoming",1,0) -> 1 | M10: =IF(B10="Outgoing",1,0) -> 0 | N10: =IF(AND(B10="Incoming",H10="Completed"),1,0) -> 1 | O10: 46237 | P10: 46237.573 | Q10: 46237.578 | R10: 355 | S10: =IF(OR(H10="failed",H10="no-answer",H10="missed-call"),1,0) -> 0 | T10: 2.4 | U10: KA | V10: KA
A11: C129 | B11: Incoming | C11: 8099389567 | D11: 640895463 | E11: Siddharth Jain | F11: Arjun Kapoor | G11: 1000000011 | H11: completed | I11: =IF(SalesData[[#This Row],[Status of Call]]="completed",1,0) -> 1 | J11: =1 -> 1 | K11: =SalesData[[#This Row],[Completed calls]]/SalesData[[#This Row],[Total calls]] -> 1 | L11: =IF(B11="incoming",1,0) -> 1 | M11: =IF(B11="Outgoing",1,0) -> 0 | N11: =IF(AND(B11="Incoming",H11="Completed"),1,0) -> 1 | O11: 46237 | P11: 46237.574 | Q11: 46237.575 | R11: 61 | S11: =IF(OR(H11="failed",H11="no-answer",H11="missed-call"),1,0) -> 0 | T11: 0.4 | U11: KA | V11: KA
A12: C137 | B12: Incoming | C12: 8099389567 | D12: 122210367 | E12: Akash Singh | F12: Pallavi Naik | G12: 1000000034 | H12: call-attempt | I12: =IF(SalesData[[#This Row],[Status of Call]]="completed",1,0) -> 0 | J12: =1 -> 1 | K12: =SalesData[[#This Row],[Completed calls]]/SalesData[[#This Row],[Total calls]] -> 0 | L12: =IF(B12="incoming",1,0) -> 1 | M12: =IF(B12="Outgoing",1,0) -> 0 | N12: =IF(AND(B12="Incoming",H12="Completed"),1,0) -> 0 | O12: 46237 | P12: 46237.596 | Q12: 46237.597 | R12: 15 | S12: =IF(OR(H12="failed",H12="no-answer",H12="missed-call"),1,0) -> 0 | U12: KA | V12: KA
A13: C138 | B13: Incoming | C13: 8099389567 | D13: 910304698 | E13: Neha Gupta | F13: Rohan Das | G13: 1000000017 | H13: missed-call | I13: =IF(SalesData[[#This Row],[Status of Call]]="completed",1,0) -> 0 | J13: =1 -> 1 | K13: =SalesData[[#This Row],[Completed calls]]/SalesData[[#This Row],[Total calls]] -> 0 | L13: =IF(B13="incoming",1,0) -> 1 | M13: =IF(B13="Outgoing",1,0) -> 0 | N13: =IF(AND(B13="Incoming",H13="Completed"),1,0) -> 0 | O13: 46237 | P13: 46237.597 | Q13: 46237.598 | R13: 50 | S13: =IF(OR(H13="failed",H13="no-answer",H13="missed-call"),1,0) -> 1 | U13: KA | V13: KA
A14: C14 | B14: Incoming | C14: 8099389567 | D14: 3632601 | E14: Varun Iyer | F14: Tanvi Kulkarni | G14: 1000000018 | H14: call-attempt | I14: =IF(SalesData[[#This Row],[Status of Call]]="completed",1,0) -> 0 | J14: =1 -> 1 | K14: =SalesData[[#This Row],[Completed calls]]/SalesData[[#This Row],[Total calls]] -> 0 | L14: =IF(B14="incoming",1,0) -> 1 | M14: =IF(B14="Outgoing",1,0) -> 0 | N14: =IF(AND(B14="Incoming",H14="Completed"),1,0) -> 0 | O14: 46236 | P14: 46236.358 | Q14: 46236.358 | R14: 18 | S14: =IF(OR(H14="failed",H14="no-answer",H14="missed-call"),1,0) -> 0 | U14: KA | V14: KA
A15: C140 | B15: Incoming | C15: 8099389567 | D15: 439248817 | E15: Nandini Das | F15: Aarav Sharma | G15: 1000000001 | H15: completed | I15: =IF(SalesData[[#This Row],[Status of Call]]="completed",1,0) -> 1 | J15: =1 -> 1 | K15: =SalesData[[#This Row],[Completed calls]]/SalesData[[#This Row],[Total calls]] -> 1 | L15: =IF(B15="incoming",1,0) -> 1 | M15: =IF(B15="Outgoing",1,0) -> 0 | N15: =IF(AND(B15="Incoming",H15="Completed"),1,0) -> 1 | O15: 46237 | P15: 46237.623 | Q15: 46237.637 | R15: 1190 | S15: =IF(OR(H15="failed",H15="no-answer",H15="missed-call"),1,0) -> 0 | T15: 8 | U15: KA | V15: KA
A16: C141 | B16: Incoming | C16: 8099389567 | D16: 248406541 | E16: Sakshi Joshi | F16: Sneha Reddy | G16: 1000000008 | H16: completed | I16: =IF(SalesData[[#This Row],[Status of Call]]="completed",1,0) -> 1 | J16: =1 -> 1 | K16: =SalesData[[#This Row],[Completed calls]]/SalesData[[#This Row],[Total calls]] -> 1 | L16: =IF(B16="incoming",1,0) -> 1 | M16: =IF(B16="Outgoing",1,0) -> 0 | N16: =IF(AND(B16="Incoming",H16="Completed"),1,0) -> 1 | O16: 46237 | P16: 46237.631 | Q16: 46237.634 | R16: 248 | S16: =IF(OR(H16="failed",H16="no-answer",H16="missed-call"),1,0) -> 0 | T16: 1.6 | U16: KA | V16: KA
A17: C143 | B17: Incoming | C17: 8099389567 | D17: 207141783 | E17: Rahul Verma | F17: Tanvi Kulkarni | G17: 1000000018 | H17: call-attempt | I17: =IF(SalesData[[#This Row],[Status of Call]]="completed",1,0) -> 0 | J17: =1 -> 1 | K17: =SalesData[[#This Row],[Completed calls]]/SalesData[[#This Row],[Total calls]] -> 0 | L17: =IF(B17="incoming",1,0) -> 1 | M17: =IF(B17="Outgoing",1,0) -> 0 | N17: =IF(AND(B17="Incoming",H17="Completed"),1,0) -> 0 | O17: 46237 | P17: 46237.638 | Q17: 46237.638 | R17: 10 | S17: =IF(OR(H17="failed",H17="no-answer",H17="missed-call"),1,0) -> 0 | U17: KA | V17: KA
A18: C144 | B18: Incoming | C18: 8099389567 | D18: 978555161 | E18: Riya Mehta | F18: Divya Sethi | G18: 1000000022 | H18: call-attempt | I18: =IF(SalesData[[#This Row],[Status of Call]]="completed",1,0) -> 0 | J18: =1 -> 1 | K18: =SalesData[[#This Row],[Completed calls]]/SalesData[[#This Row],[Total calls]] -> 0 | L18: =IF(B18="incoming",1,0) -> 1 | M18: =IF(B18="Outgoing",1,0) -> 0 | N18: =IF(AND(B18="Incoming",H18="Completed"),1,0) -> 0 | O18: 46237 | P18: 46237.64 | Q18: 46237.64 | R18: 7 | S18: =IF(OR(H18="failed",H18="no-answer",H18="missed-call"),1,0) -> 0 | U18: KA | V18: KA
A19: C148 | B19: Incoming | C19: 8099389567 | D19: 455637777 | E19: Riya Mehta | F19: Arjun Kapoor | G19: 1000000011 | H19: completed | I19: =IF(SalesData[[#This Row],[Status of Call]]="completed",1,0) -> 1 | J19: =1 -> 1 | K19: =SalesData[[#This Row],[Completed calls]]/SalesData[[#This Row],[Total calls]] -> 1 | L19: =IF(B19="incoming",1,0) -> 1 | M19: =IF(B19="Outgoing",1,0) -> 0 | N19: =IF(AND(B19="Incoming",H19="Completed"),1,0) -> 1 | O19: 46237 | P19: 46237.665 | Q19: 46237.671 | R19: 583 | S19: =IF(OR(H19="failed",H19="no-answer",H19="missed-call"),1,0) -> 0 | T19: 4 | U19: KA | V19: KA
A20: C149 | B20: Incoming | C20: 8099389567 | D20: 876036921 | E20: Vikram Patel | F20: Nandini Bose | G20: 1000000030 | H20: missed-call | I20: =IF(SalesData[[#This Row],[Status of Call]]="completed",1,0) -> 0 | J20: =1 -> 1 | K20: =SalesData[[#This Row],[Completed calls]]/SalesData[[#This Row],[Total calls]] -> 0 | L20: =IF(B20="incoming",1,0) -> 1 | M20: =IF(B20="Outgoing",1,0) -> 0 | N20: =IF(AND(B20="Incoming",H20="Completed"),1,0) -> 0 | O20: 46237 | P20: 46237.685 | Q20: 46237.685 | R20: 43 | S20: =IF(OR(H20="failed",H20="no-answer",H20="missed-call"),1,0) -> 1 | U20: KA | V20: KA
A21: C15 | B21: Incoming | C21: 8099389567 | D21: 590065495 | E21: Ishita Kapoor | F21: Ishita Gupta | G21: 1000000016 | H21: missed-call | I21: =IF(SalesData[[#This Row],[Status of Call]]="completed",1,0) -> 0 | J21: =1 -> 1 | K21: =SalesData[[#This Row],[Completed calls]]/SalesData[[#This Row],[Total calls]] -> 0 | L21: =IF(B21="incoming",1,0) -> 1 | M21: =IF(B21="Outgoing",1,0) -> 0 | N21: =IF(AND(B21="Incoming",H21="Completed"),1,0) -> 0 | O21: 46236 | P21: t | Q21: 46236.365 | R21: 82 | S21: =IF(OR(H21="failed",H21="no-answer",H21="missed-call"),1,0) -> 1 | U21: KA | V21: KA
A22: C150 | B22: Incoming | C22: 8099389567 | D22: 121125131 | E22: Vikram Patel | F22: Aarav Sharma | G22: 1000000001 | H22: call-attempt | I22: =IF(SalesData[[#This Row],[Status of Call]]="completed",1,0) -> 0 | J22: =1 -> 1 | K22: =SalesData[[#This Row],[Completed calls]]/SalesData[[#This Row],[Total calls]] -> 0 | L22: =IF(B22="incoming",1,0) -> 1 | M22: =IF(B22="Outgoing",1,0) -> 0 | N22: =IF(AND(B22="Incoming",H22="Completed"),1,0) -> 0 | O22: 46237 | P22: 46237.692 | Q22: 46237.692 | R22: 12 | S22: =IF(OR(H22="failed",H22="no-answer",H22="missed-call"),1,0) -> 0 | U22: KA | V22: KA
A23: C151 | B23: Incoming | C23: 8099389567 | D23: 480575038 | E23: Nisha Verma | F23: Rohan Das | G23: 1000000017 | H23: completed | I23: =IF(SalesData[[#This Row],[Status of Call]]="completed",1,0) -> 1 | J23: =1 -> 1 | K23: =SalesData[[#This Row],[Completed calls]]/SalesData[[#This Row],[Total calls]] -> 1 | L23: =IF(B23="incoming",1,0) -> 1 | M23: =IF(B23="Outgoing",1,0) -> 0 | N23: =IF(AND(B23="Incoming",H23="Completed"),1,0) -> 1 | O23: 46237 | P23: 46237.707 | Q23: 46237.709 | R23: 130 | S23: =IF(OR(H23="failed",H23="no-answer",H23="missed-call"),1,0) -> 0 | T23: 0.4 | U23: KA | V23: KA
A24: C152 | B24: Incoming | C24: 8099389567 | D24: 287932330 | E24: Nandini Das | F24: Gaurav Bansal | G24: 1000000033 | H24: completed | I24: =IF(SalesData[[#This Row],[Status of Call]]="completed",1,0) -> 1 | J24: =1 -> 1 | K24: =SalesData[[#This Row],[Completed calls]]/SalesData[[#This Row],[Total calls]] -> 1 | L24: =IF(B24="incoming",1,0) -> 1 | M24: =IF(B24="Outgoing",1,0) -> 0 | N24: =IF(AND(B24="Incoming",H24="Completed"),1,0) -> 1 | O24: 46237 | P24: 46237.709 | Q24: 46237.711 | R24: 155 | S24: =IF(OR(H24="failed",H24="no-answer",H24="missed-call"),1,0) -> 0 | T24: 0.8 | U24: KA | V24: KA
A25: C153 | B25: Incoming | C25: 8099389567 | D25: 823887648 | E25: Siddharth Jain | F25: Kavya Menon | G25: 1000000012 | H25: completed | I25: =IF(SalesData[[#This Row],[Status of Call]]="completed",1,0) -> 1 | J25: =1 -> 1 | K25: =SalesData[[#This Row],[Completed calls]]/SalesData[[#This Row],[Total calls]] -> 1 | L25: =IF(B25="incoming",1,0) -> 1 | M25: =IF(B25="Outgoing",1,0) -> 0 | N25: =IF(AND(B25="Incoming",H25="Completed"),1,0) -> 1 | O25: 46237 | P25: 46237.712 | Q25: 46237.718 | R25: 494 | S25: =IF(OR(H25="failed",H25="no-answer",H25="missed-call"),1,0) -> 0 | T25: 3.2 | U25: KA | V25: KA
A26: C154 | B26: Incoming | C26: 8099389567 | D26: 279744156 | E26: Ananya Sharma | F26: Gaurav Bansal | G26: 1000000033 | H26: call-attempt | I26: =IF(SalesData[[#This Row],[Status of Call]]="completed",1,0) -> 0 | J26: =1 -> 1 | K26: =SalesData[[#This Row],[Completed calls]]/SalesData[[#This Row],[Total calls]] -> 0 | L26: =IF(B26="incoming",1,0) -> 1 | M26: =IF(B26="Outgoing",1,0) -> 0 | N26: =IF(AND(B26="Incoming",H26="Completed"),1,0) -> 0 | O26: 46237 | P26: 46237.721 | Q26: 46237.721 | R26: 11 | S26: =IF(OR(H26="failed",H26="no-answer",H26="missed-call"),1,0) -> 0 | U26: KA | V26: KA
A27: C155 | B27: Incoming | C27: 8099389567 | D27: 233114113 | E27: Sanjay Nair | F27: Rahul Verma | G27: 1000000007 | H27: completed | I27: =IF(SalesData[[#This Row],[Status of Call]]="completed",1,0) -> 1 | J27: =1 -> 1 | K27: =SalesData[[#This Row],[Completed calls]]/SalesData[[#This Row],[Total calls]] -> 1 | L27: =IF(B27="incoming",1,0) -> 1 | M27: =IF(B27="Outgoing",1,0) -> 0 | N27: =IF(AND(B27="Incoming",H27="Completed"),1,0) -> 1 | O27: 46237 | P27: 46237.723 | Q27: 46237.725 | R27: 163 | S27: =IF(OR(H27="failed",H27="no-answer",H27="missed-call"),1,0) -> 0 | T27: 0.8 | U27: KA | V27: KA
A28: C156 | B28: Incoming | C28: 8099389567 | D28: 628821463 | E28: Deepak Yadav | F28: Neha Bhat | G28: 1000000020 | H28: completed | I28: =IF(SalesData[[#This Row],[Status of Call]]="completed",1,0) -> 1 | J28: =1 -> 1 | K28: =SalesData[[#This Row],[Completed calls]]/SalesData[[#This Row],[Total calls]] -> 1 | L28: =IF(B28="incoming",1,0) -> 1 | M28: =IF(B28="Outgoing",1,0) -> 0 | N28: =IF(AND(B28="Incoming",H28="Completed"),1,0) -> 1 | O28: 46237 | P28: 46237.73 | Q28: 46237.732 | R28: 96 | S28: =IF(OR(H28="failed",H28="no-answer",H28="missed-call"),1,0) -> 0 | T28: 0.4 | U28: KA | V28: KA
A29: C157 | B29: Incoming | C29: 8099389567 | D29: 379376386 | E29: Aarav Sharma | F29: Gaurav Bansal | G29: 1000000033 | H29: call-attempt | I29: =IF(SalesData[[#This Row],[Status of Call]]="completed",1,0) -> 0 | J29: =1 -> 1 | K29: =SalesData[[#This Row],[Completed calls]]/SalesData[[#This Row],[Total calls]] -> 0 | L29: =IF(B29="incoming",1,0) -> 1 | M29: =IF(B29="Outgoing",1,0) -> 0 | N29: =IF(AND(B29="Incoming",H29="Completed"),1,0) -> 0 | O29: 46237 | P29: 46237.731 | Q29: 46237.731 | R29: 11 | S29: =IF(OR(H29="failed",H29="no-answer",H29="missed-call"),1,0) -> 0 | U29: KA | V29: KA
A30: C158 | B30: Incoming | C30: 8099389567 | D30: 432037307 | E30: Riya Mehta | F30: Rohit Bedi | G30: 1000000039 | H30: call-attempt | I30: =IF(SalesData[[#This Row],[Status of Call]]="completed",1,0) -> 0 | J30: =1 -> 1 | K30: =SalesData[[#This Row],[Completed calls]]/SalesData[[#This Row],[Total calls]] -> 0 | L30: =IF(B30="incoming",1,0) -> 1 | M30: =IF(B30="Outgoing",1,0) -> 0 | N30: =IF(AND(B30="Incoming",H30="Completed"),1,0) -> 0 | O30: 46237 | P30: 46237.731 | Q30: 46237.732 | R30: 8 | S30: =IF(OR(H30="failed",H30="no-answer",H30="missed-call"),1,0) -> 0 | U30: KA | V30: KA
A31: C159 | B31: Incoming | C31: 8099389567 | D31: 401249303 | E31: Ananya Sharma | F31: Nikhil Jain | G31: 1000000013 | H31: completed | I31: =IF(SalesData[[#This Row],[Status of Call]]="completed",1,0) -> 1 | J31: =1 -> 1 | K31: =SalesData[[#This Row],[Completed calls]]/SalesData[[#This Row],[Total calls]] -> 1 | L31: =IF(B31="incoming",1,0) -> 1 | M31: =IF(B31="Outgoing",1,0) -> 0 | N31: =IF(AND(B31="Incoming",H31="Completed"),1,0) -> 1 | O31: 46237 | P31: 46237.732 | Q31: 46237.733 | R31: 156 | S31: =IF(OR(H31="failed",H31="no-answer",H31="missed-call"),1,0) -> 0 | T31: 0.4 | U31: KA | V31: KA
A32: C16 | B32: Incoming | C32: 8099389567 | D32: 416937095 | E32: Kriti Singh | F32: Varun Singh | G32: 1000000015 | H32: completed | I32: =IF(SalesData[[#This Row],[Status of Call]]="completed",1,0) -> 1 | J32: =1 -> 1 | K32: =SalesData[[#This Row],[Completed calls]]/SalesData[[#This Row],[Total calls]] -> 1 | L32: =IF(B32="incoming",1,0) -> 1 | M32: =IF(B32="Outgoing",1,0) -> 0 | N32: =IF(AND(B32="Incoming",H32="Completed"),1,0) -> 1 | O32: 46236 | P32: 46236.368 | Q32: 46236.373 | R32: 412 | S32: =IF(OR(H32="failed",H32="no-answer",H32="missed-call"),1,0) -> 0 | T32: 2.8 | U32: KA | V32: KA
A33: C160 | B33: Incoming | C33: 8099389567 | D33: 319647139 | E33: Nisha Verma | F33: Meera Joshi | G33: 1000000010 | H33: call-attempt | I33: =IF(SalesData[[#This Row],[Status of Call]]="completed",1,0) -> 0 | J33: =1 -> 1 | K33: =SalesData[[#This Row],[Completed calls]]/SalesData[[#This Row],[Total calls]] -> 0 | L33: =IF(B33="incoming",1,0) -> 1 | M33: =IF(B33="Outgoing",1,0) -> 0 | N33: =IF(AND(B33="Incoming",H33="Completed"),1,0) -> 0 | O33: 46237 | P33: 46237.733 | Q33: 46237.734 | R33: 20 | S33: =IF(OR(H33="failed",H33="no-answer",H33="missed-call"),1,0) -> 0 | U33: KA | V33: KA
A34: C161 | B34: Incoming | C34: 8099389567 | D34: 139164288 | E34: Harsh Patel | F34: Shreya Pillai | G34: 1000000024 | H34: completed | I34: =IF(SalesData[[#This Row],[Status of Call]]="completed",1,0) -> 1 | J34: =1 -> 1 | K34: =SalesData[[#This Row],[Completed calls]]/SalesData[[#This Row],[Total calls]] -> 1 | L34: =IF(B34="incoming",1,0) -> 1 | M34: =IF(B34="Outgoing",1,0) -> 0 | N34: =IF(AND(B34="Incoming",H34="Completed"),1,0) -> 1 | O34: 46237 | P34: 46237.734 | Q34: 46237.734 | R34: 62 | S34: =IF(OR(H34="failed",H34="no-answer",H34="missed-call"),1,0) -> 0 | T34: 0.4 | U34: KA | V34: KA
A35: C162 | B35: Incoming | C35: 8099389567 | D35: 290751369 | E35: Divya Rao | F35: Arjun Kapoor | G35: 1000000011 | H35: completed | I35: =IF(SalesData[[#This Row],[Status of Call]]="completed",1,0) -> 1 | J35: =1 -> 1 | K35: =SalesData[[#This Row],[Completed calls]]/SalesData[[#This Row],[Total calls]] -> 1 | L35: =IF(B35="incoming",1,0) -> 1 | M35: =IF(B35="Outgoing",1,0) -> 0 | N35: =IF(AND(B35="Incoming",H35="Completed"),1,0) -> 1 | O35: 46237 | P35: 46237.734 | Q35: 46237.744 | R35: 850 | S35: =IF(OR(H35="failed",H35="no-answer",H35="missed-call"),1,0) -> 0 | T35: 5.6 | U35: KA | V35: KA
A36: C163 | B36: Incoming | C36: 8099389567 | D36: 107059949 | E36: Aditi Shah | F36: Amit Khanna | G36: 1000000035 | H36: call-attempt | I36: =IF(SalesData[[#This Row],[Status of Call]]="completed",1,0) -> 0 | J36: =1 -> 1 | K36: =SalesData[[#This Row],[Completed calls]]/SalesData[[#This Row],[Total calls]] -> 0 | L36: =IF(B36="incoming",1,0) -> 1 | M36: =IF(B36="Outgoing",1,0) -> 0 | N36: =IF(AND(B36="Incoming",H36="Completed"),1,0) -> 0 | O36: 46237 | P36: 46237.735 | Q36: 46237.735 | R36: 9 | S36: =IF(OR(H36="failed",H36="no-answer",H36="missed-call"),1,0) -> 0 | U36: KA | V36: KA
A37: C169 | B37: Incoming | C37: 8099389567 | D37: 971503761 | E37: Varun Iyer | F37: Riya Mehta | G37: 1000000002 | H37: completed | I37: =IF(SalesData[[#This Row],[Status of Call]]="completed",1,0) -> 1 | J37: =1 -> 1 | K37: =SalesData[[#This Row],[Completed calls]]/SalesData[[#This Row],[Total calls]] -> 1 | L37: =IF(B37="incoming",1,0) -> 1 | M37: =IF(B37="Outgoing",1,0) -> 0 | N37: =IF(AND(B37="Incoming",H37="Completed"),1,0) -> 1 | O37: 46237 | P37: 46237.739 | Q37: 46237.739 | R37: 43 | S37: =IF(OR(H37="failed",H37="no-answer",H37="missed-call"),1,0) -> 0 | T37: 0.4 | U37: TN | V37: KA
A38: C17 | B38: Incoming | C38: 8099389567 | D38: 720035961 | E38: Divya Rao | F38: Aditya Rao | G38: 1000000009 | H38: missed-call | I38: =IF(SalesData[[#This Row],[Status of Call]]="completed",1,0) -> 0 | J38: =1 -> 1 | K38: =SalesData[[#This Row],[Completed calls]]/SalesData[[#This Row],[Total calls]] -> 0 | L38: =IF(B38="incoming",1,0) -> 1 | M38: =IF(B38="Outgoing",1,0) -> 0 | N38: =IF(AND(B38="Incoming",H38="Completed"),1,0) -> 0 | O38: 46236 | P38: 46236.39 | Q38: 46236.391 | R38: 56 | S38: =IF(OR(H38="failed",H38="no-answer",H38="missed-call"),1,0) -> 1 | U38: KA | V38: KA
A39: C172 | B39: Incoming | C39: 8099389567 | D39: 635859674 | E39: Rahul Verma | F39: Neha Bhat | G39: 1000000020 | H39: call-attempt | I39: =IF(SalesData[[#This Row],[Status of Call]]="completed",1,0) -> 0 | J39: =1 -> 1 | K39: =SalesData[[#This Row],[Completed calls]]/SalesData[[#This Row],[Total calls]] -> 0 | L39: =IF(B39="incoming",1,0) -> 1 | M39: =IF(B39="Outgoing",1,0) -> 0 | N39: =IF(AND(B39="Incoming",H39="Completed"),1,0) -> 0 | O39: 46237 | P39: 46237.739 | Q39: 46237.739 | R39: 22 | S39: =IF(OR(H39="failed",H39="no-answer",H39="missed-call"),1,0) -> 0 | U39: TN | V39: KA
A40: C173 | B40: Incoming | C40: 8099389567 | D40: 49531867 | E40: Riya Mehta | F40: Ishita Gupta | G40: 1000000016 | H40: completed | I40: =IF(SalesData[[#This Row],[Status of Call]]="completed",1,0) -> 1 | J40: =1 -> 1 | K40: =SalesData[[#This Row],[Completed calls]]/SalesData[[#This Row],[Total calls]] -> 1 | L40: =IF(B40="incoming",1,0) -> 1 | M40: =IF(B40="Outgoing",1,0) -> 0 | N40: =IF(AND(B40="Incoming",H40="Completed"),1,0) -> 1 | O40: 46237 | P40: 46237.74 | Q40: 46237.741 | R40: 82 | S40: =IF(OR(H40="failed",H40="no-answer",H40="missed-call"),1,0) -> 0 | T40: 0.4 | U40: TN | V40: KA
...

Sheet Calculations
A1: Salesperson Performance Calculations
A3: Sales Person Name | B3: Direction | C3: Status of Call | D3: Incoming Flag | E3: Outgoing Flag | F3: Completed Flag | G3: Completed Incoming | H3: Conversion Rate | I3: Call Duration | J3: Price for a Call | K3: Date
A4: =Raw_Data!E2 -> Sanjay Nair | B4: =Raw_Data!B2 -> Incoming | C4: =Raw_Data!H2 -> call-attempt | D4: =Raw_Data!L2 -> 1 | E4: =Raw_Data!M2 -> 0 | F4: =Raw_Data!I2 -> 0 | G4: =Raw_Data!N2 -> 0 | H4: =Raw_Data!K2 -> 0 | I4: =Raw_Data!R2 -> 8 | J4: =Raw_Data!T2 -> 0 | K4: =Raw_Data!O2 -> 46237
A5: =Raw_Data!E3 -> Pooja Shah | B5: =Raw_Data!B3 -> Incoming | C5: =Raw_Data!H3 -> call-attempt | D5: =Raw_Data!L3 -> 1 | E5: =Raw_Data!M3 -> 0 | F5: =Raw_Data!I3 -> 0 | G5: =Raw_Data!N3 -> 0 | H5: =Raw_Data!K3 -> 0 | I5: =Raw_Data!R3 -> 21 | J5: =Raw_Data!T3 -> 0 | K5: =Raw_Data!O3 -> 46237
A6: =Raw_Data!E4 -> Akash Singh | B6: =Raw_Data!B4 -> Incoming | C6: =Raw_Data!H4 -> completed | D6: =Raw_Data!L4 -> 1 | E6: =Raw_Data!M4 -> 0 | F6: =Raw_Data!I4 -> 1 | G6: =Raw_Data!N4 -> 1 | H6: =Raw_Data!K4 -> 1 | I6: =Raw_Data!R4 -> 426 | J6: =Raw_Data!T4 -> 2.8 | K6: =Raw_Data!O4 -> 46237 | V6: =SalesData[[#This Row],[Sales Person Number]] -> 925746665
A7: =Raw_Data!E5 -> Priya Nair | B7: =Raw_Data!B5 -> Incoming | C7: =Raw_Data!H5 -> completed | D7: =Raw_Data!L5 -> 1 | E7: =Raw_Data!M5 -> 0 | F7: =Raw_Data!I5 -> 1 | G7: =Raw_Data!N5 -> 1 | H7: =Raw_Data!K5 -> 1 | I7: =Raw_Data!R5 -> 97 | J7: =Raw_Data!T5 -> 0.4 | K7: =Raw_Data!O5 -> 46237
A8: =Raw_Data!E6 -> Anjali Menon | B8: =Raw_Data!B6 -> Incoming | C8: =Raw_Data!H6 -> completed | D8: =Raw_Data!L6 -> 1 | E8: =Raw_Data!M6 -> 0 | F8: =Raw_Data!I6 -> 1 | G8: =Raw_Data!N6 -> 1 | H8: =Raw_Data!K6 -> 1 | I8: =Raw_Data!R6 -> 768 | J8: =Raw_Data!T6 -> 5.2 | K8: =Raw_Data!O6 -> 46237
A9: =Raw_Data!E7 -> Shreya Iyer | B9: =Raw_Data!B7 -> Incoming | C9: =Raw_Data!H7 -> call-attempt | D9: =Raw_Data!L7 -> 1 | E9: =Raw_Data!M7 -> 0 | F9: =Raw_Data!I7 -> 0 | G9: =Raw_Data!N7 -> 0 | H9: =Raw_Data!K7 -> 0 | I9: =Raw_Data!R7 -> 7 | J9: =Raw_Data!T7 -> 0 | K9: =Raw_Data!O7 -> 46237
A10: =Raw_Data!E8 -> Meera Joshi | B10: =Raw_Data!B8 -> Incoming | C10: =Raw_Data!H8 -> completed | D10: =Raw_Data!L8 -> 1 | E10: =Raw_Data!M8 -> 0 | F10: =Raw_Data!I8 -> 1 | G10: =Raw_Data!N8 -> 1 | H10: =Raw_Data!K8 -> 1 | I10: =Raw_Data!R8 -> 34 | J10: =Raw_Data!T8 -> 0.4 | K10: =Raw_Data!O8 -> 46237
A11: =Raw_Data!E9 -> Karan Malhotra | B11: =Raw_Data!B9 -> Incoming | C11: =Raw_Data!H9 -> missed-call | D11: =Raw_Data!L9 -> 1 | E11: =Raw_Data!M9 -> 0 | F11: =Raw_Data!I9 -> 0 | G11: =Raw_Data!N9 -> 0 | H11: =Raw_Data!K9 -> 0 | I11: =Raw_Data!R9 -> 46 | J11: =Raw_Data!T9 -> 0 | K11: =Raw_Data!O9 -> 46237
A12: =Raw_Data!E10 -> Rohan Mehta | B12: =Raw_Data!B10 -> Incoming | C12: =Raw_Data!H10 -> completed | D12: =Raw_Data!L10 -> 1 | E12: =Raw_Data!M10 -> 0 | F12: =Raw_Data!I10 -> 1 | G12: =Raw_Data!N10 -> 1 | H12: =Raw_Data!K10 -> 1 | I12: =Raw_Data!R10 -> 355 | J12: =Raw_Data!T10 -> 2.4 | K12: =Raw_Data!O10 -> 46237
A13: =Raw_Data!E11 -> Siddharth Jain | B13: =Raw_Data!B11 -> Incoming | C13: =Raw_Data!H11 -> completed | D13: =Raw_Data!L11 -> 1 | E13: =Raw_Data!M11 -> 0 | F13: =Raw_Data!I11 -> 1 | G13: =Raw_Data!N11 -> 1 | H13: =Raw_Data!K11 -> 1 | I13: =Raw_Data!R11 -> 61 | J13: =Raw_Data!T11 -> 0.4 | K13: =Raw_Data!O11 -> 46237
A14: =Raw_Data!E12 -> Akash Singh | B14: =Raw_Data!B12 -> Incoming | C14: =Raw_Data!H12 -> call-attempt | D14: =Raw_Data!L12 -> 1 | E14: =Raw_Data!M12 -> 0 | F14: =Raw_Data!I12 -> 0 | G14: =Raw_Data!N12 -> 0 | H14: =Raw_Data!K12 -> 0 | I14: =Raw_Data!R12 -> 15 | J14: =Raw_Data!T12 -> 0 | K14: =Raw_Data!O12 -> 46237
A15: =Raw_Data!E13 -> Neha Gupta | B15: =Raw_Data!B13 -> Incoming | C15: =Raw_Data!H13 -> missed-call | D15: =Raw_Data!L13 -> 1 | E15: =Raw_Data!M13 -> 0 | F15: =Raw_Data!I13 -> 0 | G15: =Raw_Data!N13 -> 0 | H15: =Raw_Data!K13 -> 0 | I15: =Raw_Data!R13 -> 50 | J15: =Raw_Data!T13 -> 0 | K15: =Raw_Data!O13 -> 46237
A16: =Raw_Data!E14 -> Varun Iyer | B16: =Raw_Data!B14 -> Incoming | C16: =Raw_Data!H14 -> call-attempt | D16: =Raw_Data!L14 -> 1 | E16: =Raw_Data!M14 -> 0 | F16: =Raw_Data!I14 -> 0 | G16: =Raw_Data!N14 -> 0 | H16: =Raw_Data!K14 -> 0 | I16: =Raw_Data!R14 -> 18 | J16: =Raw_Data!T14 -> 0 | K16: =Raw_Data!O14 -> 46236
A17: =Raw_Data!E15 -> Nandini Das | B17: =Raw_Data!B15 -> Incoming | C17: =Raw_Data!H15 -> completed | D17: =Raw_Data!L15 -> 1 | E17: =Raw_Data!M15 -> 0 | F17: =Raw_Data!I15 -> 1 | G17: =Raw_Data!N15 -> 1 | H17: =Raw_Data!K15 -> 1 | I17: =Raw_Data!R15 -> 1190 | J17: =Raw_Data!T15 -> 8 | K17: =Raw_Data!O15 -> 46237
A18: =Raw_Data!E16 -> Sakshi Joshi | B18: =Raw_Data!B16 -> Incoming | C18: =Raw_Data!H16 -> completed | D18: =Raw_Data!L16 -> 1 | E18: =Raw_Data!M16 -> 0 | F18: =Raw_Data!I16 -> 1 | G18: =Raw_Data!N16 -> 1 | H18: =Raw_Data!K16 -> 1 | I18: =Raw_Data!R16 -> 248 | J18: =Raw_Data!T16 -> 1.6 | K18: =Raw_Data!O16 -> 46237
... A371: =Raw_Data!E369 -> Varun Iyer | B371: =Raw_Data!B369 -> Outgoing | C371: =Raw_Data!H369 -> completed | D371: =Raw_Data!L369 -> 0 | E371: =Raw_Data!M369 -> 1 | F371: =Raw_Data!I369 -> 1 | G371: =Raw_Data!N369 -> 0 | H371: =Raw_Data!K369 -> 1 | I371: =Raw_Data!R369 -> 46 | J371: =Raw_Data!T369 -> 1.15 | K371: =Raw_Data!O369 -> 46237

Sheet Dashboard
A1: Salesperson Performance & Call Analytics Dashboard
A3: Total calls | C3: Incoming Call | E3: Outgoing Call | G3: Completed Call
A4: =GETPIVOTDATA("Sum of Total calls",Pivot_Tables!A3) -> 368 | C4: =GETPIVOTDATA("Incoming Flag",Pivot_Tables!A3) -> 200 | E4: =A4-C4 -> 168 | G4: =GETPIVOTDATA("Sum of Completed calls",Pivot_Tables!A3) -> 175
A14: Completion Rate | C14: Conversions | E14: Conversion Rate | G14: Call Revenue
A15: =IFERROR(G4/A4,0) -> 0.47554348 | C15: =GETPIVOTDATA("Sum of CONVERSION Rate",Pivot_Tables!$A$3) -> 175 | E15: =IFERROR(C15/A4,0) -> 0.47554348 | G15: =GETPIVOTDATA("Sum of Price for a call",Pivot_Tables!$A$3) -> 411.05
